Workbook

Sheet Summary
A1: Scenario | B1: Price | C1: ARV | D1: Total cost | E1: Profit | F1: Margin | G1: ROI | H1: Annualized ROI | I1: Max offer | J1: Headroom
A2: S1 | B2: =S1!B2 -> 420000 | C2: =S1!B30 -> 1420799.9 | D2: =S1!B52 -> 1313240.3 | E2: =S1!B53 -> 107559.59 | F2: =S1!B54 -> 0.0757 | G2: =S1!B56 -> 0.3369 | H2: =S1!B57 -> 0.4492 | I2: =S1!B61 -> 324271.11 | J2: =S1!B62 -> -95728.89
A3: S2 | B3: =S2!B2 -> 300000 | C3: =S2!B24 -> 1489400.5 | D3: =S2!B46 -> 1251174.3 | E3: =S2!B47 -> 238226.17 | F3: =S2!B48 -> 0.1599 | G3: =S2!B50 -> 0.7958 | H3: =S2!B51 -> 1.061 | I3: =S2!B55 -> 313436.17 | J3: =S2!B56 -> 13436.17
A4: S3 | B4: =S3!B2 -> 495000 | C4: =S3!B24 -> 678417.76 | D4: =S3!B46 -> 1191258.5 | E4: =S3!B47 -> -512840.76 | F4: =S3!B48 -> -0.7559 | G4: =S3!B50 -> -1.6987 | H4: =S3!B51 -> -2.2649 | I4: =S3!B55 -> none | J4: =S3!B56

Sheet Assumptions
A1: Label | B1: Value | C1: Note | D1: Key
A2: acq closing pct | B2: 1 | C2: Acquisition closing costs, percent of price | D2: as.acq_closing_pct
A3: demo flat | B3: 2500 | C3: Demolition flat amount | D3: as.demo_flat
A4: demo per sqft | B4: 8 | C4: Demolition per existing sq ft | D4: as.demo_per_sqft
A5: demo fallback sqft | B5: 1500 | C5: Existing sq ft assumed when unknown | D5: as.demo_fallback_sqft
A6: hard cost psf | B6: 190 | C6: Hard cost per buildable sq ft | D6: as.hard_cost_psf
A7: contingency pct | B7: 5 | C7: Contingency, percent of hard cost | D7: as.contingency_pct
A8: soft cost pct | B8: 12 | C8: Soft costs, percent of hard cost | D8: as.soft_cost_pct
A9: build share pct | B9: 70 | C9: Share of hold spent building, percent | D9: as.build_share_pct
A10: ltc pct | B10: 80 | C10: Loan to cost, percent | D10: as.ltc_pct
A11: rate pct | B11: 10 | C11: Annual interest rate, percent | D11: as.rate_pct
A12: points pct | B12: 2 | C12: Loan points, percent of loan | D12: as.points_pct
A13: draw count | B13: 5 | C13: Number of construction draws | D13: as.draw_count
... A31: rule default living share pct | B31: 50 | C31: Default zoning: living share of gross, percent | D31: as.rule.default.living_share_pct

Sheet S1
A1: Label | B1: Value | C1: Note | D1: Key | E1: At max offer | F1: At-max key | G1: psf_i helper
A2: List price (P) | B2: 420000 | C2: Input | D2: in.price
A3: Lot sq ft (L) | B3: 6400 | C3: Input | D3: in.lot_sqft
A4: Zoning | B4: R-7.5(A) | C4: Input; no rule row means default | D4: in.zoning
A5: Vacant | B5: =FALSE() -> FALSE | C5: Input | D5: in.is_vacant
A6: Existing sq ft | B6: 1150 | C6: Input; blank means unknown | D6: in.existing_sqft
A7: Comp 1 price | B7: 1330000 | C7: Input | D7: in.comp.1.price
A8: Comp 1 area | B8: 3000 | C8: Input; used only if area >= min comp sq ft | D8: in.comp.1.area | G8: =IF(B8>=Assumptions!$B$24,ROUND(B7/B8,4),"") -> 443.3333
A9: Comp 2 price | B9: 1420000 | C9: Input | D9: in.comp.2.price
A10: Comp 2 area | B10: 3150 | C10: Input; used only if area >= min comp sq ft | D10: in.comp.2.area | G10: =IF(B10>=Assumptions!$B$24,ROUND(B9/B10,4),"") -> 450.7937
A11: Comp 3 price | B11: 1250000 | C11: Input | D11: in.comp.3.price
A12: Comp 3 area | B12: 2800 | C12: Input; used only if area >= min comp sq ft | D12: in.comp.3.area | G12: =IF(B12>=Assumptions!$B$24,ROUND(B11/B12,4),"") -> 446.4286
A13: Comp 4 price | B13: 1480000 | C13: Input | D13: in.comp.4.price
A14: Comp 4 area | B14: 3300 | C14: Input; used only if area >= min comp sq ft | D14: in.comp.4.area | G14: =IF(B14>=Assumptions!$B$24,ROUND(B13/B14,4),"") -> 448.4848
A15: Comp 5 price | B15: 1190000 | C15: Input | D15: in.comp.5.price
A16: Comp 5 area | B16: 2650 | C16: Input; used only if area >= min comp sq ft | D16: in.comp.5.area | G16: =IF(B16>=Assumptions!$B$24,ROUND(B15/B16,4),"") -> 449.0566
A17: Comp 6 price | B17: 1390000 | C17: Input | D17: in.comp.6.price
A18: Comp 6 area | B18: 3100 | C18: Input; used only if area >= min comp sq ft | D18: in.comp.6.area | G18: =IF(B18>=Assumptions!$B$24,ROUND(B17/B18,4),"") -> 448.3871
A19: Comp 7 price | B19: 1520000 | C19: Input | D19: in.comp.7.price
A20: Comp 7 area | B20: 3350 | C20: Input; used only if area >= min comp sq ft | D20: in.comp.7.area | G20: =IF(B20>=Assumptions!$B$24,ROUND(B19/B20,4),"") -> 453.7313
A21: Rule: coverage % | B21: =IF(ISNUMBER(MATCH("as.rule."&B4&".coverage_pct",Assumptions!$D$2:$D$31,0)),INDEX(Assumptions!$B$2:$B$31,MATCH("as.rule."&B4&".coverage_pct",Assumptions!$D$2:$D$31,0)),INDEX(Assumptions!$B$2:$B$31,MATCH("as.rule.default.coverage_pct",Assumptions!$D$2:$D$31,0))) -> 45 | C21: Zoning rule row, or default when none | D21: sizing.rule_coverage_pct
A22: Rule: stories | B22: =IF(ISNUMBER(MATCH("as.rule."&B4&".stories",Assumptions!$D$2:$D$31,0)),INDEX(Assumptions!$B$2:$B$31,MATCH("as.rule."&B4&".stories",Assumptions!$D$2:$D$31,0)),INDEX(Assumptions!$B$2:$B$31,MATCH("as.rule.default.stories",Assumptions!$D$2:$D$31,0))) -> 2 | C22: Zoning rule row, or default when none | D22: sizing.rule_stories
A23: Rule: living share % | B23: =IF(ISNUMBER(MATCH("as.rule."&B4&".living_share_pct",Assumptions!$D$2:$D$31,0)),INDEX(Assumptions!$B$2:$B$31,MATCH("as.rule."&B4&".living_share_pct",Assumptions!$D$2:$D$31,0)),INDEX(Assumptions!$B$2:$B$31,MATCH("as.rule.default.living_share_pct",Assumptions!$D$2:$D$31,0))) -> 55 | C23: Zoning rule row, or default when none | D23: sizing.rule_living_share_pct
A24: Footprint sq ft | B24: =B3*B21/100 -> 2880 | C24: Lot x coverage % / 100 | D24: sizing.footprint
A25: Gross sq ft | B25: =B24*B22 -> 5760 | C25: Footprint x stories | D25: sizing.gross
A26: Uncapped living sq ft | B26: =B25*B23/100 -> 3168 | C26: Gross x living share % / 100 | D26: sizing.uncapped
A27: Buildable sq ft (Q) | B27: =ROUND(MIN(MAX(B26,Assumptions!$B$21),Assumptions!$B$22),0) -> 3168 | C27: ROUND(MIN(MAX(uncapped, min), max), 0) | D27: sizing.buildable_sqft
A28: Comps used | B28: =COUNT(G7:G20) -> 7 | C28: Count of comps with area >= min comp sq ft | D28: arv.comp_count_used
A29: Median price per sq ft | B29: =MEDIAN(G7:G20) -> 448.4848 | C29: Median of psf_i helper column (column G) | D29: arv.median_psf
A30: ARV (V) | B30: =ROUND(B29*B27*(1+Assumptions!$B$25/100),2) -> 1420799.9 | C30: ROUND(median psf x Q x (1 + premium %/100), 2) | D30: arv.arv
A31: Acquisition closing | B31: =ROUND(B2*Assumptions!$B$2/100,2) -> 4200 | C31: ROUND(P x closing % / 100, 2) | D31: cost.acq_closing | E31: =IF(ISNUMBER($B$61),ROUND($B$61*Assumptions!$B$2/100,2),"") -> 3242.71 | F31: atmax.cost.acq_closing
A32: Demolition (D) | B32: =IF(B5,0,ROUND(Assumptions!$B$3+Assumptions!$B$4*IF(ISBLANK(B6),Assumptions!$B$5,B6),2)) -> 11700 | C32: 0 if vacant, else ROUND(flat + per sq ft x existing or fallback, 2) | D32: cost.demolition | E32: =IF(ISNUMBER($B$61),IF(B5,0,ROUND(Assumptions!$B$3+Assumptions!$B$4*IF(ISBLANK(B6),Assumptions!$B$5,B6),2)),"") -> 11700 | F32: atmax.cost.demolition
A33: Hard cost (K) | B33: =ROUND(B27*Assumptions!$B$6,2) -> 601920 | C33: ROUND(Q x hard cost per sq ft, 2) | D33: cost.hard | E33: =IF(ISNUMBER($B$61),ROUND(B27*Assumptions!$B$6,2),"") -> 601920 | F33: atmax.cost.hard
A34: Contingency (Kc) | B34: =ROUND(B33*Assumptions!$B$7/100,2) -> 30096 | C34: ROUND(K x contingency % / 100, 2) | D34: cost.contingency | E34: =IF(ISNUMBER($B$61),ROUND(E33*Assumptions!$B$7/100,2),"") -> 30096 | F34: atmax.cost.contingency
A35: Soft costs (S) | B35: =ROUND(B33*Assumptions!$B$8/100,2) -> 72230.4 | C35: ROUND(K x soft % / 100, 2) | D35: cost.soft | E35: =IF(ISNUMBER($B$61),ROUND(E33*Assumptions!$B$8/100,2),"") -> 72230.4 | F35: atmax.cost.soft
A36: Months of construction (C) | B36: =Assumptions!$B$15*Assumptions!$B$9/100 -> 6.3 | C36: H x build share % / 100 | D36: fin.months_construction | E36: =IF(ISNUMBER($B$61),Assumptions!$B$15*Assumptions!$B$9/100,"") -> 6.3 | F36: atmax.fin.months_construction
A37: Months on sale (Mo) | B37: =Assumptions!$B$15-B36 -> 2.7 | C37: H - C | D37: fin.months_sale | E37: =IF(ISNUMBER($B$61),Assumptions!$B$15-E36,"") -> 2.7 | F37: atmax.fin.months_sale
A38: Financeable cost (F) | B38: =B2+B32+B33+B34+B35 -> 1135946.4 | C38: P + D + K + Kc + S | D38: fin.financeable | E38: =IF(ISNUMBER($B$61),$B$61+E32+E33+E34+E35,"") -> 1040217.5 | F38: atmax.fin.financeable
A39: Loan (Ln) | B39: =ROUND(B38*Assumptions!$B$10/100,2) -> 908757.12 | C39: ROUND(F x LTC % / 100, 2) | D39: fin.loan | E39: =IF(ISNUMBER($B$61),ROUND(E38*Assumptions!$B$10/100,2),"") -> 832174.01 | F39: atmax.fin.loan
A40: Interest, front-drawn | B40: =ROUND((B2+B32+B35)*Assumptions!$B$10/100*Assumptions!$B$11/100/12*Assumptions!$B$15,2) -> 30235.82 | C40: ROUND((P + D + S) x l x i x H, 2) | D40: fin.interest_front | E40: =IF(ISNUMBER($B$61),ROUND(($B$61+E32+E35)*Assumptions!$B$10/100*Assumptions!$B$11/100/12*Assumptions!$B$15,2),"") -> 24492.09 | F40: atmax.fin.interest_front
...

Sheet S2
A1: Label | B1: Value | C1: Note | D1: Key | E1: At max offer | F1: At-max key | G1: psf_i helper
A2: List price (P) | B2: 300000 | C2: Input | D2: in.price
A3: Lot sq ft (L) | B3: 10134 | C3: Input | D3: in.lot_sqft
A4: Zoning | B4: R-7.5(A) | C4: Input; no rule row means default | D4: in.zoning
A5: Vacant | B5: =TRUE() -> TRUE | C5: Input | D5: in.is_vacant
A6: Existing sq ft | C6: Input; blank means unknown | D6: in.existing_sqft
A7: Comp 1 price | B7: 1450000 | C7: Input | D7: in.comp.1.price
A8: Comp 1 area | B8: 3400 | C8: Input; used only if area >= min comp sq ft | D8: in.comp.1.area | G8: =IF(B8>=Assumptions!$B$24,ROUND(B7/B8,4),"") -> 426.4706
A9: Comp 2 price | B9: 1380000 | C9: Input | D9: in.comp.2.price
A10: Comp 2 area | B10: 3250 | C10: Input; used only if area >= min comp sq ft | D10: in.comp.2.area | G10: =IF(B10>=Assumptions!$B$24,ROUND(B9/B10,4),"") -> 424.6154
A11: Comp 3 price | B11: 1500000 | C11: Input | D11: in.comp.3.price
A12: Comp 3 area | B12: 3600 | C12: Input; used only if area >= min comp sq ft | D12: in.comp.3.area | G12: =IF(B12>=Assumptions!$B$24,ROUND(B11/B12,4),"") -> 416.6667
A13: Comp 4 price | B13: 1280000 | C13: Input | D13: in.comp.4.price
A14: Comp 4 area | B14: 3000 | C14: Input; used only if area >= min comp sq ft | D14: in.comp.4.area | G14: =IF(B14>=Assumptions!$B$24,ROUND(B13/B14,4),"") -> 426.6667
A15: Rule: coverage % | B15: =IF(ISNUMBER(MATCH("as.rule."&B4&".coverage_pct",Assumptions!$D$2:$D$31,0)),INDEX(Assumptions!$B$2:$B$31,MATCH("as.rule."&B4&".coverage_pct",Assumptions!$D$2:$D$31,0)),INDEX(Assumptions!$B$2:$B$31,MATCH("as.rule.default.coverage_pct",Assumptions!$D$2:$D$31,0))) -> 45 | C15: Zoning rule row, or default when none | D15: sizing.rule_coverage_pct
A16: Rule: stories | B16: =IF(ISNUMBER(MATCH("as.rule."&B4&".stories",Assumptions!$D$2:$D$31,0)),INDEX(Assumptions!$B$2:$B$31,MATCH("as.rule."&B4&".stories",Assumptions!$D$2:$D$31,0)),INDEX(Assumptions!$B$2:$B$31,MATCH("as.rule.default.stories",Assumptions!$D$2:$D$31,0))) -> 2 | C16: Zoning rule row, or default when none | D16: sizing.rule_stories
A17: Rule: living share % | B17: =IF(ISNUMBER(MATCH("as.rule."&B4&".living_share_pct",Assumptions!$D$2:$D$31,0)),INDEX(Assumptions!$B$2:$B$31,MATCH("as.rule."&B4&".living_share_pct",Assumptions!$D$2:$D$31,0)),INDEX(Assumptions!$B$2:$B$31,MATCH("as.rule.default.living_share_pct",Assumptions!$D$2:$D$31,0))) -> 55 | C17: Zoning rule row, or default when none | D17: sizing.rule_living_share_pct
A18: Footprint sq ft | B18: =B3*B15/100 -> 4560.3 | C18: Lot x coverage % / 100 | D18: sizing.footprint
A19: Gross sq ft | B19: =B18*B16 -> 9120.6 | C19: Footprint x stories | D19: sizing.gross
A20: Uncapped living sq ft | B20: =B19*B17/100 -> 5016.33 | C20: Gross x living share % / 100 | D20: sizing.uncapped
A21: Buildable sq ft (Q) | B21: =ROUND(MIN(MAX(B20,Assumptions!$B$21),Assumptions!$B$22),0) -> 3500 | C21: ROUND(MIN(MAX(uncapped, min), max), 0) | D21: sizing.buildable_sqft
A22: Comps used | B22: =COUNT(G7:G14) -> 4 | C22: Count of comps with area >= min comp sq ft | D22: arv.comp_count_used
A23: Median price per sq ft | B23: =MEDIAN(G7:G14) -> 425.543 | C23: Median of psf_i helper column (column G) | D23: arv.median_psf
A24: ARV (V) | B24: =ROUND(B23*B21*(1+Assumptions!$B$25/100),2) -> 1489400.5 | C24: ROUND(median psf x Q x (1 + premium %/100), 2) | D24: arv.arv
A25: Acquisition closing | B25: =ROUND(B2*Assumptions!$B$2/100,2) -> 3000 | C25: ROUND(P x closing % / 100, 2) | D25: cost.acq_closing | E25: =IF(ISNUMBER($B$55),ROUND($B$55*Assumptions!$B$2/100,2),"") -> 3134.36 | F25: atmax.cost.acq_closing
A26: Demolition (D) | B26: =IF(B5,0,ROUND(Assumptions!$B$3+Assumptions!$B$4*IF(ISBLANK(B6),Assumptions!$B$5,B6),2)) -> 0 | C26: 0 if vacant, else ROUND(flat + per sq ft x existing or fallback, 2) | D26: cost.demolition | E26: =IF(ISNUMBER($B$55),IF(B5,0,ROUND(Assumptions!$B$3+Assumptions!$B$4*IF(ISBLANK(B6),Assumptions!$B$5,B6),2)),"") -> 0 | F26: atmax.cost.demolition
A27: Hard cost (K) | B27: =ROUND(B21*Assumptions!$B$6,2) -> 665000 | C27: ROUND(Q x hard cost per sq ft, 2) | D27: cost.hard | E27: =IF(ISNUMBER($B$55),ROUND(B21*Assumptions!$B$6,2),"") -> 665000 | F27: atmax.cost.hard
A28: Contingency (Kc) | B28: =ROUND(B27*Assumptions!$B$7/100,2) -> 33250 | C28: ROUND(K x contingency % / 100, 2) | D28: cost.contingency | E28: =IF(ISNUMBER($B$55),ROUND(E27*Assumptions!$B$7/100,2),"") -> 33250 | F28: atmax.cost.contingency
A29: Soft costs (S) | B29: =ROUND(B27*Assumptions!$B$8/100,2) -> 79800 | C29: ROUND(K x soft % / 100, 2) | D29: cost.soft | E29: =IF(ISNUMBER($B$55),ROUND(E27*Assumptions!$B$8/100,2),"") -> 79800 | F29: atmax.cost.soft
A30: Months of construction (C) | B30: =Assumptions!$B$15*Assumptions!$B$9/100 -> 6.3 | C30: H x build share % / 100 | D30: fin.months_construction | E30: =IF(ISNUMBER($B$55),Assumptions!$B$15*Assumptions!$B$9/100,"") -> 6.3 | F30: atmax.fin.months_construction
A31: Months on sale (Mo) | B31: =Assumptions!$B$15-B30 -> 2.7 | C31: H - C | D31: fin.months_sale | E31: =IF(ISNUMBER($B$55),Assumptions!$B$15-E30,"") -> 2.7 | F31: atmax.fin.months_sale
A32: Financeable cost (F) | B32: =B2+B26+B27+B28+B29 -> 1078050 | C32: P + D + K + Kc + S | D32: fin.financeable | E32: =IF(ISNUMBER($B$55),$B$55+E26+E27+E28+E29,"") -> 1091486.2 | F32: atmax.fin.financeable
A33: Loan (Ln) | B33: =ROUND(B32*Assumptions!$B$10/100,2) -> 862440 | C33: ROUND(F x LTC % / 100, 2) | D33: fin.loan | E33: =IF(ISNUMBER($B$55),ROUND(E32*Assumptions!$B$10/100,2),"") -> 873188.94 | F33: atmax.fin.loan
A34: Interest, front-drawn | B34: =ROUND((B2+B26+B29)*Assumptions!$B$10/100*Assumptions!$B$11/100/12*Assumptions!$B$15,2) -> 22788 | C34: ROUND((P + D + S) x l x i x H, 2) | D34: fin.interest_front | E34: =IF(ISNUMBER($B$55),ROUND(($B$55+E26+E29)*Assumptions!$B$10/100*Assumptions!$B$11/100/12*Assumptions!$B$15,2),"") -> 23594.17 | F34: atmax.fin.interest_front
A35: Interest, progressive | B35: =ROUND((B27+B28)*Assumptions!$B$10/100*Assumptions!$B$11/100/12*(B30/2+B31),2) -> 27231.75 | C35: ROUND((K + Kc) x l x i x (C/2 + Mo), 2) | D35: fin.interest_progressive | E35: =IF(ISNUMBER($B$55),ROUND((E27+E28)*Assumptions!$B$10/100*Assumptions!$B$11/100/12*(E30/2+E31),2),"") -> 27231.75 | F35: atmax.fin.interest_progressive
A36: Interest | B36: =B34+B35 -> 50019.75 | C36: Front + progressive | D36: fin.interest | E36: =IF(ISNUMBER($B$55),E34+E35,"") -> 50825.92 | F36: atmax.fin.interest
A37: Points | B37: =ROUND(B33*Assumptions!$B$12/100,2) -> 17248.8 | C37: ROUND(Ln x points % / 100, 2) | D37: fin.points | E37: =IF(ISNUMBER($B$55),ROUND(E33*Assumptions!$B$12/100,2),"") -> 17463.78 | F37: atmax.fin.points
A38: Draw fees | B38: =Assumptions!$B$13*Assumptions!$B$14 -> 1000 | C38: Draw count x draw fee | D38: fin.draw_fees | E38: =IF(ISNUMBER($B$55),Assumptions!$B$13*Assumptions!$B$14,"") -> 1000 | F38: atmax.fin.draw_fees
A39: Financing total | B39: =B36+B37+B38 -> 68268.55 | C39: Interest + points + draw fees | D39: fin.total | E39: =IF(ISNUMBER($B$55),E36+E37+E38,"") -> 69289.7 | F39: atmax.fin.total
A40: Holding: property tax | B40: =ROUND(B2*Assumptions!$B$16/100*Assumptions!$B$15/12,2) -> 5010.49 | C40: ROUND(P x tax % / 100 x H / 12, 2) | D40: hold.tax | E40: =IF(ISNUMBER($B$55),ROUND($B$55*Assumptions!$B$16/100*Assumptions!$B$15/12,2),"") -> 5234.9 | F40: atmax.hold.tax
...

Sheet S3
A1: Label | B1: Value | C1: Note | D1: Key | E1: At max offer | F1: At-max key | G1: psf_i helper
A2: List price (P) | B2: 495000 | C2: Input | D2: in.price
A3: Lot sq ft (L) | B3: 6200 | C3: Input | D3: in.lot_sqft
A4: Zoning | B4: CD-12 | C4: Input; no rule row means default | D4: in.zoning
A5: Vacant | B5: =FALSE() -> FALSE | C5: Input | D5: in.is_vacant
A6: Existing sq ft | C6: Input; blank means unknown | D6: in.existing_sqft
A7: Comp 1 price | B7: 640000 | C7: Input | D7: in.comp.1.price
A8: Comp 1 area | B8: 2300 | C8: Input; used only if area >= min comp sq ft | D8: in.comp.1.area | G8: =IF(B8>=Assumptions!$B$24,ROUND(B7/B8,4),"") -> 278.2609
A9: Comp 2 price | B9: 690000 | C9: Input | D9: in.comp.2.price
A10: Comp 2 area | B10: 2500 | C10: Input; used only if area >= min comp sq ft | D10: in.comp.2.area | G10: =IF(B10>=Assumptions!$B$24,ROUND(B9/B10,4),"") -> 276
A11: Comp 3 price | B11: 610000 | C11: Input | D11: in.comp.3.price
A12: Comp 3 area | B12: 2250 | C12: Input; used only if area >= min comp sq ft | D12: in.comp.3.area | G12: =IF(B12>=Assumptions!$B$24,ROUND(B11/B12,4),"") -> 271.1111
A13: Comp 4 price | B13: 720000 | C13: Input | D13: in.comp.4.price
A14: Comp 4 area | B14: 2700 | C14: Input; used only if area >= min comp sq ft | D14: in.comp.4.area | G14: =IF(B14>=Assumptions!$B$24,ROUND(B13/B14,4),"") -> 266.6667
A15: Rule: coverage % | B15: =IF(ISNUMBER(MATCH("as.rule."&B4&".coverage_pct",Assumptions!$D$2:$D$31,0)),INDEX(Assumptions!$B$2:$B$31,MATCH("as.rule."&B4&".coverage_pct",Assumptions!$D$2:$D$31,0)),INDEX(Assumptions!$B$2:$B$31,MATCH("as.rule.default.coverage_pct",Assumptions!$D$2:$D$31,0))) -> 40 | C15: Zoning rule row, or default when none | D15: sizing.rule_coverage_pct
A16: Rule: stories | B16: =IF(ISNUMBER(MATCH("as.rule."&B4&".stories",Assumptions!$D$2:$D$31,0)),INDEX(Assumptions!$B$2:$B$31,MATCH("as.rule."&B4&".stories",Assumptions!$D$2:$D$31,0)),INDEX(Assumptions!$B$2:$B$31,MATCH("as.rule.default.stories",Assumptions!$D$2:$D$31,0))) -> 2 | C16: Zoning rule row, or default when none | D16: sizing.rule_stories
A17: Rule: living share % | B17: =IF(ISNUMBER(MATCH("as.rule."&B4&".living_share_pct",Assumptions!$D$2:$D$31,0)),INDEX(Assumptions!$B$2:$B$31,MATCH("as.rule."&B4&".living_share_pct",Assumptions!$D$2:$D$31,0)),INDEX(Assumptions!$B$2:$B$31,MATCH("as.rule.default.living_share_pct",Assumptions!$D$2:$D$31,0))) -> 50 | C17: Zoning rule row, or default when none | D17: sizing.rule_living_share_pct
A18: Footprint sq ft | B18: =B3*B15/100 -> 2480 | C18: Lot x coverage % / 100 | D18: sizing.footprint
A19: Gross sq ft | B19: =B18*B16 -> 4960 | C19: Footprint x stories | D19: sizing.gross
A20: Uncapped living sq ft | B20: =B19*B17/100 -> 2480 | C20: Gross x living share % / 100 | D20: sizing.uncapped
A21: Buildable sq ft (Q) | B21: =ROUND(MIN(MAX(B20,Assumptions!$B$21),Assumptions!$B$22),0) -> 2480 | C21: ROUND(MIN(MAX(uncapped, min), max), 0) | D21: sizing.buildable_sqft
A22: Comps used | B22: =COUNT(G7:G14) -> 4 | C22: Count of comps with area >= min comp sq ft | D22: arv.comp_count_used
A23: Median price per sq ft | B23: =MEDIAN(G7:G14) -> 273.55555 | C23: Median of psf_i helper column (column G) | D23: arv.median_psf
A24: ARV (V) | B24: =ROUND(B23*B21*(1+Assumptions!$B$25/100),2) -> 678417.76 | C24: ROUND(median psf x Q x (1 + premium %/100), 2) | D24: arv.arv
A25: Acquisition closing | B25: =ROUND(B2*Assumptions!$B$2/100,2) -> 4950 | C25: ROUND(P x closing % / 100, 2) | D25: cost.acq_closing | E25: =IF(ISNUMBER($B$55),ROUND($B$55*Assumptions!$B$2/100,2),"") | F25: atmax.cost.acq_closing
A26: Demolition (D) | B26: =IF(B5,0,ROUND(Assumptions!$B$3+Assumptions!$B$4*IF(ISBLANK(B6),Assumptions!$B$5,B6),2)) -> 14500 | C26: 0 if vacant, else ROUND(flat + per sq ft x existing or fallback, 2) | D26: cost.demolition | E26: =IF(ISNUMBER($B$55),IF(B5,0,ROUND(Assumptions!$B$3+Assumptions!$B$4*IF(ISBLANK(B6),Assumptions!$B$5,B6),2)),"") | F26: atmax.cost.demolition
A27: Hard cost (K) | B27: =ROUND(B21*Assumptions!$B$6,2) -> 471200 | C27: ROUND(Q x hard cost per sq ft, 2) | D27: cost.hard | E27: =IF(ISNUMBER($B$55),ROUND(B21*Assumptions!$B$6,2),"") | F27: atmax.cost.hard
A28: Contingency (Kc) | B28: =ROUND(B27*Assumptions!$B$7/100,2) -> 23560 | C28: ROUND(K x contingency % / 100, 2) | D28: cost.contingency | E28: =IF(ISNUMBER($B$55),ROUND(E27*Assumptions!$B$7/100,2),"") | F28: atmax.cost.contingency
A29: Soft costs (S) | B29: =ROUND(B27*Assumptions!$B$8/100,2) -> 56544 | C29: ROUND(K x soft % / 100, 2) | D29: cost.soft | E29: =IF(ISNUMBER($B$55),ROUND(E27*Assumptions!$B$8/100,2),"") | F29: atmax.cost.soft
A30: Months of construction (C) | B30: =Assumptions!$B$15*Assumptions!$B$9/100 -> 6.3 | C30: H x build share % / 100 | D30: fin.months_construction | E30: =IF(ISNUMBER($B$55),Assumptions!$B$15*Assumptions!$B$9/100,"") | F30: atmax.fin.months_construction
A31: Months on sale (Mo) | B31: =Assumptions!$B$15-B30 -> 2.7 | C31: H - C | D31: fin.months_sale | E31: =IF(ISNUMBER($B$55),Assumptions!$B$15-E30,"") | F31: atmax.fin.months_sale
A32: Financeable cost (F) | B32: =B2+B26+B27+B28+B29 -> 1060804 | C32: P + D + K + Kc + S | D32: fin.financeable | E32: =IF(ISNUMBER($B$55),$B$55+E26+E27+E28+E29,"") | F32: atmax.fin.financeable
A33: Loan (Ln) | B33: =ROUND(B32*Assumptions!$B$10/100,2) -> 848643.2 | C33: ROUND(F x LTC % / 100, 2) | D33: fin.loan | E33: =IF(ISNUMBER($B$55),ROUND(E32*Assumptions!$B$10/100,2),"") | F33: atmax.fin.loan
A34: Interest, front-drawn | B34: =ROUND((B2+B26+B29)*Assumptions!$B$10/100*Assumptions!$B$11/100/12*Assumptions!$B$15,2) -> 33962.64 | C34: ROUND((P + D + S) x l x i x H, 2) | D34: fin.interest_front | E34: =IF(ISNUMBER($B$55),ROUND(($B$55+E26+E29)*Assumptions!$B$10/100*Assumptions!$B$11/100/12*Assumptions!$B$15,2),"") | F34: atmax.fin.interest_front
A35: Interest, progressive | B35: =ROUND((B27+B28)*Assumptions!$B$10/100*Assumptions!$B$11/100/12*(B30/2+B31),2) -> 19295.64 | C35: ROUND((K + Kc) x l x i x (C/2 + Mo), 2) | D35: fin.interest_progressive | E35: =IF(ISNUMBER($B$55),ROUND((E27+E28)*Assumptions!$B$10/100*Assumptions!$B$11/100/12*(E30/2+E31),2),"") | F35: atmax.fin.interest_progressive
A36: Interest | B36: =B34+B35 -> 53258.28 | C36: Front + progressive | D36: fin.interest | E36: =IF(ISNUMBER($B$55),E34+E35,"") | F36: atmax.fin.interest
A37: Points | B37: =ROUND(B33*Assumptions!$B$12/100,2) -> 16972.86 | C37: ROUND(Ln x points % / 100, 2) | D37: fin.points | E37: =IF(ISNUMBER($B$55),ROUND(E33*Assumptions!$B$12/100,2),"") | F37: atmax.fin.points
A38: Draw fees | B38: =Assumptions!$B$13*Assumptions!$B$14 -> 1000 | C38: Draw count x draw fee | D38: fin.draw_fees | E38: =IF(ISNUMBER($B$55),Assumptions!$B$13*Assumptions!$B$14,"") | F38: atmax.fin.draw_fees
A39: Financing total | B39: =B36+B37+B38 -> 71231.14 | C39: Interest + points + draw fees | D39: fin.total | E39: =IF(ISNUMBER($B$55),E36+E37+E38,"") | F39: atmax.fin.total
A40: Holding: property tax | B40: =ROUND(B2*Assumptions!$B$16/100*Assumptions!$B$15/12,2) -> 8267.31 | C40: ROUND(P x tax % / 100 x H / 12, 2) | D40: hold.tax | E40: =IF(ISNUMBER($B$55),ROUND($B$55*Assumptions!$B$16/100*Assumptions!$B$15/12,2),"") | F40: atmax.hold.tax
...

Sheet Sensitivity
A1: arv_delta_pct | B1: hard_cost_delta_pct | C1: hold_months | D1: arv | E1: hard_cost | F1: total_cost | G1: profit | H1: margin | I1: roi | J1: sell_commission | K1: sell_closing | L1: sell_total | M1: contingency | N1: soft | O1: insurance | P1: months_construction | Q1: months_sale | R1: financeable | S1: loan | T1: interest_front | U1: interest_progressive | V1: interest | W1: points | X1: draw_fees | Y1: fin_total | Z1: tax | AA1: hold_total | AB1: cash_invested
A2: -10 | B2: -10 | C2: 6 | D2: =ROUND(S1!$B$30*(1+A2/100),2) -> 1278719.9 | E2: =ROUND(S1!$B$33*(1+B2/100),2) -> 541728 | F2: =S1!$B$2+S1!$B$31+S1!$B$32+E2+M2+N2+Y2+AA2+L2 -> 1207890.2 | G2: =D2-F2 -> 70829.69 | H2: =ROUND(G2/D2,4) -> 0.0554 | I2: =IF(AB2<=0,"",ROUND(G2/AB2,4)) -> 0.2541 | J2: =ROUND(D2*Assumptions!$B$18/100,2) -> 63935.99 | K2: =ROUND(D2*Assumptions!$B$19/100,2) -> 12787.2 | L2: =J2+K2 -> 76723.19 | M2: =ROUND(E2*Assumptions!$B$7/100,2) -> 27086.4 | N2: =ROUND(E2*Assumptions!$B$8/100,2) -> 65007.36 | O2: =ROUND(E2*Assumptions!$B$17/100*C2/12,2) -> 4062.96 | P2: =C2*Assumptions!$B$9/100 -> 4.2 | Q2: =C2-P2 -> 1.8 | R2: =S1!$B$2+S1!$B$32+E2+M2+N2 -> 1065521.8 | S2: =ROUND(R2*Assumptions!$B$10/100,2) -> 852417.41 | T2: =ROUND((S1!$B$2+S1!$B$32+N2)*Assumptions!$B$10/100*Assumptions!$B$11/100/12*C2,2) -> 19868.29 | U2: =ROUND((E2+M2)*Assumptions!$B$10/100*Assumptions!$B$11/100/12*(P2/2+Q2),2) -> 14789.17 | V2: =T2+U2 -> 34657.46 | W2: =ROUND(S2*Assumptions!$B$12/100,2) -> 17048.35 | X2: =Assumptions!$B$13*Assumptions!$B$14 -> 1000 | Y2: =V2+W2+X2 -> 52705.81 | Z2: =ROUND(S1!$B$2*Assumptions!$B$16/100*C2/12,2) -> 4676.46 | AA2: =Z2+O2 -> 8739.42 | AB2: =F2-L2-S2 -> 278749.58
A3: -10 | B3: -10 | C3: 9 | D3: =ROUND(S1!$B$30*(1+A3/100),2) -> 1278719.9 | E3: =ROUND(S1!$B$33*(1+B3/100),2) -> 541728 | F3: =S1!$B$2+S1!$B$31+S1!$B$32+E3+M3+N3+Y3+AA3+L3 -> 1229588.6 | G3: =D3-F3 -> 49131.24 | H3: =ROUND(G3/D3,4) -> 0.0384 | I3: =IF(AB3<=0,"",ROUND(G3/AB3,4)) -> 0.1635 | J3: =ROUND(D3*Assumptions!$B$18/100,2) -> 63935.99 | K3: =ROUND(D3*Assumptions!$B$19/100,2) -> 12787.2 | L3: =J3+K3 -> 76723.19 | M3: =ROUND(E3*Assumptions!$B$7/100,2) -> 27086.4 | N3: =ROUND(E3*Assumptions!$B$8/100,2) -> 65007.36 | O3: =ROUND(E3*Assumptions!$B$17/100*C3/12,2) -> 6094.44 | P3: =C3*Assumptions!$B$9/100 -> 6.3 | Q3: =C3-P3 -> 2.7 | R3: =S1!$B$2+S1!$B$32+E3+M3+N3 -> 1065521.8 | S3: =ROUND(R3*Assumptions!$B$10/100,2) -> 852417.41 | T3: =ROUND((S1!$B$2+S1!$B$32+N3)*Assumptions!$B$10/100*Assumptions!$B$11/100/12*C3,2) -> 29802.44 | U3: =ROUND((E3+M3)*Assumptions!$B$10/100*Assumptions!$B$11/100/12*(P3/2+Q3),2) -> 22183.76 | V3: =T3+U3 -> 51986.2 | W3: =ROUND(S3*Assumptions!$B$12/100,2) -> 17048.35 | X3: =Assumptions!$B$13*Assumptions!$B$14 -> 1000 | Y3: =V3+W3+X3 -> 70034.55 | Z3: =ROUND(S1!$B$2*Assumptions!$B$16/100*C3/12,2) -> 7014.69 | AA3: =Z3+O3 -> 13109.13 | AB3: =F3-L3-S3 -> 300448.03
A4: -10 | B4: -10 | C4: 12 | D4: =ROUND(S1!$B$30*(1+A4/100),2) -> 1278719.9 | E4: =ROUND(S1!$B$33*(1+B4/100),2) -> 541728 | F4: =S1!$B$2+S1!$B$31+S1!$B$32+E4+M4+N4+Y4+AA4+L4 -> 1251287.1 | G4: =D4-F4 -> 27432.79 | H4: =ROUND(G4/D4,4) -> 0.0215 | I4: =IF(AB4<=0,"",ROUND(G4/AB4,4)) -> 0.0852 | J4: =ROUND(D4*Assumptions!$B$18/100,2) -> 63935.99 | K4: =ROUND(D4*Assumptions!$B$19/100,2) -> 12787.2 | L4: =J4+K4 -> 76723.19 | M4: =ROUND(E4*Assumptions!$B$7/100,2) -> 27086.4 | N4: =ROUND(E4*Assumptions!$B$8/100,2) -> 65007.36 | O4: =ROUND(E4*Assumptions!$B$17/100*C4/12,2) -> 8125.92 | P4: =C4*Assumptions!$B$9/100 -> 8.4 | Q4: =C4-P4 -> 3.6 | R4: =S1!$B$2+S1!$B$32+E4+M4+N4 -> 1065521.8 | S4: =ROUND(R4*Assumptions!$B$10/100,2) -> 852417.41 | T4: =ROUND((S1!$B$2+S1!$B$32+N4)*Assumptions!$B$10/100*Assumptions!$B$11/100/12*C4,2) -> 39736.59 | U4: =ROUND((E4+M4)*Assumptions!$B$10/100*Assumptions!$B$11/100/12*(P4/2+Q4),2) -> 29578.35 | V4: =T4+U4 -> 69314.94 | W4: =ROUND(S4*Assumptions!$B$12/100,2) -> 17048.35 | X4: =Assumptions!$B$13*Assumptions!$B$14 -> 1000 | Y4: =V4+W4+X4 -> 87363.29 | Z4: =ROUND(S1!$B$2*Assumptions!$B$16/100*C4/12,2) -> 9352.92 | AA4: =Z4+O4 -> 17478.84 | AB4: =F4-L4-S4 -> 322146.48
A5: -10 | B5: 0 | C5: 6 | D5: =ROUND(S1!$B$30*(1+A5/100),2) -> 1278719.9 | E5: =ROUND(S1!$B$33*(1+B5/100),2) -> 601920 | F5: =S1!$B$2+S1!$B$31+S1!$B$32+E5+M5+N5+Y5+AA5+L5 -> 1281825.2 | G5: =D5-F5 -> -3105.36 | H5: =ROUND(G5/D5,4) -> -0.0024 | I5: =IF(AB5<=0,"",ROUND(G5/AB5,4)) -> -0.0105 | J5: =ROUND(D5*Assumptions!$B$18/100,2) -> 63935.99 | K5: =ROUND(D5*Assumptions!$B$19/100,2) -> 12787.2 | L5: =J5+K5 -> 76723.19 | M5: =ROUND(E5*Assumptions!$B$7/100,2) -> 30096 | N5: =ROUND(E5*Assumptions!$B$8/100,2) -> 72230.4 | O5: =ROUND(E5*Assumptions!$B$17/100*C5/12,2) -> 4514.4 | P5: =C5*Assumptions!$B$9/100 -> 4.2 | Q5: =C5-P5 -> 1.8 | R5: =S1!$B$2+S1!$B$32+E5+M5+N5 -> 1135946.4 | S5: =ROUND(R5*Assumptions!$B$10/100,2) -> 908757.12 | T5: =ROUND((S1!$B$2+S1!$B$32+N5)*Assumptions!$B$10/100*Assumptions!$B$11/100/12*C5,2) -> 20157.22 | U5: =ROUND((E5+M5)*Assumptions!$B$10/100*Assumptions!$B$11/100/12*(P5/2+Q5),2) -> 16432.42 | V5: =T5+U5 -> 36589.64 | W5: =ROUND(S5*Assumptions!$B$12/100,2) -> 18175.14 | X5: =Assumptions!$B$13*Assumptions!$B$14 -> 1000 | Y5: =V5+W5+X5 -> 55764.78 | Z5: =ROUND(S1!$B$2*Assumptions!$B$16/100*C5/12,2) -> 4676.46 | AA5: =Z5+O5 -> 9190.86 | AB5: =F5-L5-S5 -> 296344.92
A6: -10 | B6: 0 | C6: 9 | D6: =ROUND(S1!$B$30*(1+A6/100),2) -> 1278719.9 | E6: =ROUND(S1!$B$33*(1+B6/100),2) -> 601920 | F6: =S1!$B$2+S1!$B$31+S1!$B$32+E6+M6+N6+Y6+AA6+L6 -> 1304715.5 | G6: =D6-F6 -> -25995.59 | H6: =ROUND(G6/D6,4) -> -0.0203 | I6: =IF(AB6<=0,"",ROUND(G6/AB6,4)) -> -0.0814 | J6: =ROUND(D6*Assumptions!$B$18/100,2) -> 63935.99 | K6: =ROUND(D6*Assumptions!$B$19/100,2) -> 12787.2 | L6: =J6+K6 -> 76723.19 | M6: =ROUND(E6*Assumptions!$B$7/100,2) -> 30096 | N6: =ROUND(E6*Assumptions!$B$8/100,2) -> 72230.4 | O6: =ROUND(E6*Assumptions!$B$17/100*C6/12,2) -> 6771.6 | P6: =C6*Assumptions!$B$9/100 -> 6.3 | Q6: =C6-P6 -> 2.7 | R6: =S1!$B$2+S1!$B$32+E6+M6+N6 -> 1135946.4 | S6: =ROUND(R6*Assumptions!$B$10/100,2) -> 908757.12 | T6: =ROUND((S1!$B$2+S1!$B$32+N6)*Assumptions!$B$10/100*Assumptions!$B$11/100/12*C6,2) -> 30235.82 | U6: =ROUND((E6+M6)*Assumptions!$B$10/100*Assumptions!$B$11/100/12*(P6/2+Q6),2) -> 24648.62 | V6: =T6+U6 -> 54884.44 | W6: =ROUND(S6*Assumptions!$B$12/100,2) -> 18175.14 | X6: =Assumptions!$B$13*Assumptions!$B$14 -> 1000 | Y6: =V6+W6+X6 -> 74059.58 | Z6: =ROUND(S1!$B$2*Assumptions!$B$16/100*C6/12,2) -> 7014.69 | AA6: =Z6+O6 -> 13786.29 | AB6: =F6-L6-S6 -> 319235.15
A7: -10 | B7: 0 | C7: 12 | D7: =ROUND(S1!$B$30*(1+A7/100),2) -> 1278719.9 | E7: =ROUND(S1!$B$33*(1+B7/100),2) -> 601920 | F7: =S1!$B$2+S1!$B$31+S1!$B$32+E7+M7+N7+Y7+AA7+L7 -> 1327605.7 | G7: =D7-F7 -> -48885.84 | H7: =ROUND(G7/D7,4) -> -0.0382 | I7: =IF(AB7<=0,"",ROUND(G7/AB7,4)) -> -0.1429 | J7: =ROUND(D7*Assumptions!$B$18/100,2) -> 63935.99 | K7: =ROUND(D7*Assumptions!$B$19/100,2) -> 12787.2 | L7: =J7+K7 -> 76723.19 | M7: =ROUND(E7*Assumptions!$B$7/100,2) -> 30096 | N7: =ROUND(E7*Assumptions!$B$8/100,2) -> 72230.4 | O7: =ROUND(E7*Assumptions!$B$17/100*C7/12,2) -> 9028.8 | P7: =C7*Assumptions!$B$9/100 -> 8.4 | Q7: =C7-P7 -> 3.6 | R7: =S1!$B$2+S1!$B$32+E7+M7+N7 -> 1135946.4 | S7: =ROUND(R7*Assumptions!$B$10/100,2) -> 908757.12 | T7: =ROUND((S1!$B$2+S1!$B$32+N7)*Assumptions!$B$10/100*Assumptions!$B$11/100/12*C7,2) -> 40314.43 | U7: =ROUND((E7+M7)*Assumptions!$B$10/100*Assumptions!$B$11/100/12*(P7/2+Q7),2) -> 32864.83 | V7: =T7+U7 -> 73179.26 | W7: =ROUND(S7*Assumptions!$B$12/100,2) -> 18175.14 | X7: =Assumptions!$B$13*Assumptions!$B$14 -> 1000 | Y7: =V7+W7+X7 -> 92354.4 | Z7: =ROUND(S1!$B$2*Assumptions!$B$16/100*C7/12,2) -> 9352.92 | AA7: =Z7+O7 -> 18381.72 | AB7: =F7-L7-S7 -> 342125.4
A8: -10 | B8: 10 | C8: 6 | D8: =ROUND(S1!$B$30*(1+A8/100),2) -> 1278719.9 | E8: =ROUND(S1!$B$33*(1+B8/100),2) -> 662112 | F8: =S1!$B$2+S1!$B$31+S1!$B$32+E8+M8+N8+Y8+AA8+L8 -> 1355760.3 | G8: =D8-F8 -> -77040.4 | H8: =ROUND(G8/D8,4) -> -0.0602 | I8: =IF(AB8<=0,"",ROUND(G8/AB8,4)) -> -0.2454 | J8: =ROUND(D8*Assumptions!$B$18/100,2) -> 63935.99 | K8: =ROUND(D8*Assumptions!$B$19/100,2) -> 12787.2 | L8: =J8+K8 -> 76723.19 | M8: =ROUND(E8*Assumptions!$B$7/100,2) -> 33105.6 | N8: =ROUND(E8*Assumptions!$B$8/100,2) -> 79453.44 | O8: =ROUND(E8*Assumptions!$B$17/100*C8/12,2) -> 4965.84 | P8: =C8*Assumptions!$B$9/100 -> 4.2 | Q8: =C8-P8 -> 1.8 | R8: =S1!$B$2+S1!$B$32+E8+M8+N8 -> 1206371 | S8: =ROUND(R8*Assumptions!$B$10/100,2) -> 965096.83 | T8: =ROUND((S1!$B$2+S1!$B$32+N8)*Assumptions!$B$10/100*Assumptions!$B$11/100/12*C8,2) -> 20446.14 | U8: =ROUND((E8+M8)*Assumptions!$B$10/100*Assumptions!$B$11/100/12*(P8/2+Q8),2) -> 18075.66 | V8: =T8+U8 -> 38521.8 | W8: =ROUND(S8*Assumptions!$B$12/100,2) -> 19301.94 | X8: =Assumptions!$B$13*Assumptions!$B$14 -> 1000 | Y8: =V8+W8+X8 -> 58823.74 | Z8: =ROUND(S1!$B$2*Assumptions!$B$16/100*C8/12,2) -> 4676.46 | AA8: =Z8+O8 -> 9642.3 | AB8: =F8-L8-S8 -> 313940.25
A9: -10 | B9: 10 | C9: 9 | D9: =ROUND(S1!$B$30*(1+A9/100),2) -> 1278719.9 | E9: =ROUND(S1!$B$33*(1+B9/100),2) -> 662112 | F9: =S1!$B$2+S1!$B$31+S1!$B$32+E9+M9+N9+Y9+AA9+L9 -> 1379842.3 | G9: =D9-F9 -> -101122.45 | H9: =ROUND(G9/D9,4) -> -0.0791 | I9: =IF(AB9<=0,"",ROUND(G9/AB9,4)) -> -0.2992 | J9: =ROUND(D9*Assumptions!$B$18/100,2) -> 63935.99 | K9: =ROUND(D9*Assumptions!$B$19/100,2) -> 12787.2 | L9: =J9+K9 -> 76723.19 | M9: =ROUND(E9*Assumptions!$B$7/100,2) -> 33105.6 | N9: =ROUND(E9*Assumptions!$B$8/100,2) -> 79453.44 | O9: =ROUND(E9*Assumptions!$B$17/100*C9/12,2) -> 7448.76 | P9: =C9*Assumptions!$B$9/100 -> 6.3 | Q9: =C9-P9 -> 2.7 | R9: =S1!$B$2+S1!$B$32+E9+M9+N9 -> 1206371 | S9: =ROUND(R9*Assumptions!$B$10/100,2) -> 965096.83 | T9: =ROUND((S1!$B$2+S1!$B$32+N9)*Assumptions!$B$10/100*Assumptions!$B$11/100/12*C9,2) -> 30669.21 | U9: =ROUND((E9+M9)*Assumptions!$B$10/100*Assumptions!$B$11/100/12*(P9/2+Q9),2) -> 27113.49 | V9: =T9+U9 -> 57782.7 | W9: =ROUND(S9*Assumptions!$B$12/100,2) -> 19301.94 | X9: =Assumptions!$B$13*Assumptions!$B$14 -> 1000 | Y9: =V9+W9+X9 -> 78084.64 | Z9: =ROUND(S1!$B$2*Assumptions!$B$16/100*C9/12,2) -> 7014.69 | AA9: =Z9+O9 -> 14463.45 | AB9: =F9-L9-S9 -> 338022.3
A10: -10 | B10: 10 | C10: 12 | D10: =ROUND(S1!$B$30*(1+A10/100),2) -> 1278719.9 | E10: =ROUND(S1!$B$33*(1+B10/100),2) -> 662112 | F10: =S1!$B$2+S1!$B$31+S1!$B$32+E10+M10+N10+Y10+AA10+L10 -> 1403924.4 | G10: =D10-F10 -> -125204.5 | H10: =ROUND(G10/D10,4) -> -0.0979 | I10: =IF(AB10<=0,"",ROUND(G10/AB10,4)) -> -0.3458 | J10: =ROUND(D10*Assumptions!$B$18/100,2) -> 63935.99 | K10: =ROUND(D10*Assumptions!$B$19/100,2) -> 12787.2 | L10: =J10+K10 -> 76723.19 | M10: =ROUND(E10*Assumptions!$B$7/100,2) -> 33105.6 | N10: =ROUND(E10*Assumptions!$B$8/100,2) -> 79453.44 | O10: =ROUND(E10*Assumptions!$B$17/100*C10/12,2) -> 9931.68 | P10: =C10*Assumptions!$B$9/100 -> 8.4 | Q10: =C10-P10 -> 3.6 | R10: =S1!$B$2+S1!$B$32+E10+M10+N10 -> 1206371 | S10: =ROUND(R10*Assumptions!$B$10/100,2) -> 965096.83 | T10: =ROUND((S1!$B$2+S1!$B$32+N10)*Assumptions!$B$10/100*Assumptions!$B$11/100/12*C10,2) -> 40892.28 | U10: =ROUND((E10+M10)*Assumptions!$B$10/100*Assumptions!$B$11/100/12*(P10/2+Q10),2) -> 36151.32 | V10: =T10+U10 -> 77043.6 | W10: =ROUND(S10*Assumptions!$B$12/100,2) -> 19301.94 | X10: =Assumptions!$B$13*Assumptions!$B$14 -> 1000 | Y10: =V10+W10+X10 -> 97345.54 | Z10: =ROUND(S1!$B$2*Assumptions!$B$16/100*C10/12,2) -> 9352.92 | AA10: =Z10+O10 -> 19284.6 | AB10: =F10-L10-S10 -> 362104.35
A11: -10 | B11: 20 | C11: 6 | D11: =ROUND(S1!$B$30*(1+A11/100),2) -> 1278719.9 | E11: =ROUND(S1!$B$33*(1+B11/100),2) -> 722304 | F11: =S1!$B$2+S1!$B$31+S1!$B$32+E11+M11+N11+Y11+AA11+L11 -> 1429695.3 | G11: =D11-F11 -> -150975.43 | H11: =ROUND(G11/D11,4) -> -0.1181 | I11: =IF(AB11<=0,"",ROUND(G11/AB11,4)) -> -0.4554 | J11: =ROUND(D11*Assumptions!$B$18/100,2) -> 63935.99 | K11: =ROUND(D11*Assumptions!$B$19/100,2) -> 12787.2 | L11: =J11+K11 -> 76723.19 | M11: =ROUND(E11*Assumptions!$B$7/100,2) -> 36115.2 | N11: =ROUND(E11*Assumptions!$B$8/100,2) -> 86676.48 | O11: =ROUND(E11*Assumptions!$B$17/100*C11/12,2) -> 5417.28 | P11: =C11*Assumptions!$B$9/100 -> 4.2 | Q11: =C11-P11 -> 1.8 | R11: =S1!$B$2+S1!$B$32+E11+M11+N11 -> 1276795.7 | S11: =ROUND(R11*Assumptions!$B$10/100,2) -> 1021436.5 | T11: =ROUND((S1!$B$2+S1!$B$32+N11)*Assumptions!$B$10/100*Assumptions!$B$11/100/12*C11,2) -> 20735.06 | U11: =ROUND((E11+M11)*Assumptions!$B$10/100*Assumptions!$B$11/100/12*(P11/2+Q11),2) -> 19718.9 | V11: =T11+U11 -> 40453.96 | W11: =ROUND(S11*Assumptions!$B$12/100,2) -> 20428.73 | X11: =Assumptions!$B$13*Assumptions!$B$14 -> 1000 | Y11: =V11+W11+X11 -> 61882.69 | Z11: =ROUND(S1!$B$2*Assumptions!$B$16/100*C11/12,2) -> 4676.46 | AA11: =Z11+O11 -> 10093.74 | AB11: =F11-L11-S11 -> 331535.57
A12: -10 | B12: 20 | C12: 9 | D12: =ROUND(S1!$B$30*(1+A12/100),2) -> 1278719.9 | E12: =ROUND(S1!$B$33*(1+B12/100),2) -> 722304 | F12: =S1!$B$2+S1!$B$31+S1!$B$32+E12+M12+N12+Y12+AA12+L12 -> 1454969.1 | G12: =D12-F12 -> -176249.28 | H12: =ROUND(G12/D12,4) -> -0.1378 | I12: =IF(AB12<=0,"",ROUND(G12/AB12,4)) -> -0.494 | J12: =ROUND(D12*Assumptions!$B$18/100,2) -> 63935.99 | K12: =ROUND(D12*Assumptions!$B$19/100,2) -> 12787.2 | L12: =J12+K12 -> 76723.19 | M12: =ROUND(E12*Assumptions!$B$7/100,2) -> 36115.2 | N12: =ROUND(E12*Assumptions!$B$8/100,2) -> 86676.48 | O12: =ROUND(E12*Assumptions!$B$17/100*C12/12,2) -> 8125.92 | P12: =C12*Assumptions!$B$9/100 -> 6.3 | Q12: =C12-P12 -> 2.7 | R12: =S1!$B$2+S1!$B$32+E12+M12+N12 -> 1276795.7 | S12: =ROUND(R12*Assumptions!$B$10/100,2) -> 1021436.5 | T12: =ROUND((S1!$B$2+S1!$B$32+N12)*Assumptions!$B$10/100*Assumptions!$B$11/100/12*C12,2) -> 31102.59 | U12: =ROUND((E12+M12)*Assumptions!$B$10/100*Assumptions!$B$11/100/12*(P12/2+Q12),2) -> 29578.35 | V12: =T12+U12 -> 60680.94 | W12: =ROUND(S12*Assumptions!$B$12/100,2) -> 20428.73 | X12: =Assumptions!$B$13*Assumptions!$B$14 -> 1000 | Y12: =V12+W12+X12 -> 82109.67 | Z12: =ROUND(S1!$B$2*Assumptions!$B$16/100*C12/12,2) -> 7014.69 | AA12: =Z12+O12 -> 15140.61 | AB12: =F12-L12-S12 -> 356809.42
A13: -10 | B13: 20 | C13: 12 | D13: =ROUND(S1!$B$30*(1+A13/100),2) -> 1278719.9 | E13: =ROUND(S1!$B$33*(1+B13/100),2) -> 722304 | F13: =S1!$B$2+S1!$B$31+S1!$B$32+E13+M13+N13+Y13+AA13+L13 -> 1480243 | G13: =D13-F13 -> -201523.13 | H13: =ROUND(G13/D13,4) -> -0.1576 | I13: =IF(AB13<=0,"",ROUND(G13/AB13,4)) -> -0.5274 | J13: =ROUND(D13*Assumptions!$B$18/100,2) -> 63935.99 | K13: =ROUND(D13*Assumptions!$B$19/100,2) -> 12787.2 | L13: =J13+K13 -> 76723.19 | M13: =ROUND(E13*Assumptions!$B$7/100,2) -> 36115.2 | N13: =ROUND(E13*Assumptions!$B$8/100,2) -> 86676.48 | O13: =ROUND(E13*Assumptions!$B$17/100*C13/12,2) -> 10834.56 | P13: =C13*Assumptions!$B$9/100 -> 8.4 | Q13: =C13-P13 -> 3.6 | R13: =S1!$B$2+S1!$B$32+E13+M13+N13 -> 1276795.7 | S13: =ROUND(R13*Assumptions!$B$10/100,2) -> 1021436.5 | T13: =ROUND((S1!$B$2+S1!$B$32+N13)*Assumptions!$B$10/100*Assumptions!$B$11/100/12*C13,2) -> 41470.12 | U13: =ROUND((E13+M13)*Assumptions!$B$10/100*Assumptions!$B$11/100/12*(P13/2+Q13),2) -> 39437.8 | V13: =T13+U13 -> 80907.92 | W13: =ROUND(S13*Assumptions!$B$12/100,2) -> 20428.73 | X13: =Assumptions!$B$13*Assumptions!$B$14 -> 1000 | Y13: =V13+W13+X13 -> 102336.65 | Z13: =ROUND(S1!$B$2*Assumptions!$B$16/100*C13/12,2) -> 9352.92 | AA13: =Z13+O13 -> 20187.48 | AB13: =F13-L13-S13 -> 382083.27
... A61: 10 | B61: 20 | C61: 12 | D61: =ROUND(S1!$B$30*(1+A61/100),2) -> 1562879.8 | E61: =ROUND(S1!$B$33*(1+B61/100),2) -> 722304 | F61: =S1!$B$2+S1!$B$31+S1!$B$32+E61+M61+N61+Y61+AA61+L61 -> 1497292.6 | G61: =D61-F61 -> 65587.24 | H61: =ROUND(G61/D61,4) -> 0.042 | I61: =IF(AB61<=0,"",ROUND(G61/AB61,4)) -> 0.1717 | J61: =ROUND(D61*Assumptions!$B$18/100,2) -> 78143.99 | K61: =ROUND(D61*Assumptions!$B$19/100,2) -> 15628.8 | L61: =J61+K61 -> 93772.79 | M61: =ROUND(E61*Assumptions!$B$7/100,2) -> 36115.2 | N61: =ROUND(E61*Assumptions!$B$8/100,2) -> 86676.48 | O61: =ROUND(E61*Assumptions!$B$17/100*C61/12,2) -> 10834.56 | P61: =C61*Assumptions!$B$9/100 -> 8.4 | Q61: =C61-P61 -> 3.6 | R61: =S1!$B$2+S1!$B$32+E61+M61+N61 -> 1276795.7 | S61: =ROUND(R61*Assumptions!$B$10/100,2) -> 1021436.5 | T61: =ROUND((S1!$B$2+S1!$B$32+N61)*Assumptions!$B$10/100*Assumptions!$B$11/100/12*C61,2) -> 41470.12 | U61: =ROUND((E61+M61)*Assumptions!$B$10/100*Assumptions!$B$11/100/12*(P61/2+Q61),2) -> 39437.8 | V61: =T61+U61 -> 80907.92 | W61: =ROUND(S61*Assumptions!$B$12/100,2) -> 20428.73 | X61: =Assumptions!$B$13*Assumptions!$B$14 -> 1000 | Y61: =V61+W61+X61 -> 102336.65 | Z61: =ROUND(S1!$B$2*Assumptions!$B$16/100*C61/12,2) -> 9352.92 | AA61: =Z61+O61 -> 20187.48 | AB61: =F61-L61-S61 -> 382083.27
